Workbook

Sheet Summary
A1: Expense Tracking Summary - 2025
A3: Month | B3: Total Expenses (AUD) | C3: 2025-12-25 | D3: Status | E3: Last Updated
A4: December | B4: ='Dec 2025'!D100 -> 13352.95 | C4: =COUNTA('Dec 2025'!A2:A99) -> 36 | D4: Complete - Audited | E4: 2025-12-23
A5: November | B5: ='Nov 2025'!D100 -> 8972.4 | C5: =COUNTA('Nov 2025'!A2:A99) -> 28 | D5: Complete - Audited | E5: 2025-12-23
A6: October | B6: ='Oct 2025'!D101 -> 8805.985 | C6: =COUNTA('Oct 2025'!A2:A100) -> 28 | D6: Complete - Audited | E6: 2025-12-23
A7: September | B7: ='Sep 2025'!D100 -> 4602.52 | C7: =COUNTA('Sep 2025'!A2:A99) -> 26 | D7: Complete - Audited | E7: 2025-12-23
A8: August | B8: 4964.87 | C8: =COUNTA('Aug 2025'!A2:A99) -> 23 | D8: 2025-12-25 | E8: 2025-12-23
A9: July | B9: ='Jul 2025'!D86 -> 5063.87 | C9: =COUNTA('Jul 2025'!A2:A85) -> 22 | D9: Complete - Audited | E9: 2025-12-23
A10: June | B10: ='Jun 2025'!D104 -> 741.29 | C10: =COUNTA('Jun 2025'!A2:A103) -> 10 | D10: Complete - Audited | E10: 2025-12-23
A11: May | B11: ='May 2025'!D106 -> 5457.175 | C11: =COUNTA('May 2025'!A2:A105) -> 19 | D11: Complete - Audited | E11: 2025-12-23
A12: April | B12: ='Apr 2025'!D100 -> 12340.54 | C12: =COUNTA('Apr 2025'!A2:A99) -> 34 | D12: Complete - Audited | E12: 2025-12-23
A14: Audit Summary
A15: Total Transactions Added: 65
A17: Breakdown by Month:
A18: December 2025: +11 transactions
A19: November 2025: +12 transactions
A20: October 2025: +7 transactions
A21: September 2025: +12 transactions
A22: August 2025: +11 transactions
A23: July 2025: +1 transaction
A24: June 2025: +4 transactions
A25: May 2025: +6 transactions
A26: April 2025: +1 transaction | B26: ='Dec 2025'!D100 -> 13352.95
A27: November 2025: | B27: ='Nov 2025'!D100 -> 8972.4
A28: AUDIT COMPLETE | B28: ='Oct 2025'!D101 -> 8805.985
A29: All 9 months (April - December 2025) have been comprehensively audited | B29: ='Sep 2025'!D100 -> 4602.52
A30: Audit completed on: 2025-12-23 | B30: ='Aug 2025'!D100 -> 2642.695
A31: July 2025: | B31: ='Jul 2025'!D86 -> 5063.87
A32: Final Statistics:
A33: Total months audited: 9
A34: Total transactions added: 65
A35: Original transaction count: ~73
A36: Final transaction count: 138
A37: Grand Total (Apr-Dec 2025): | B37: =SUM(B4:B12) -> 64301.6

Sheet Sheet1
A2: 22/12/2025 | B2: CARLA TAYLOR t/as CARLORBIZ | C2: Payment sent via Thriday | D2: 5000 | E2: AUD | F2: N-T | G2: Business Transfer | H2: Sent | I2: Thriday | J2: View Email | L2: THRIDAY-489427000-20251222 | M2: 19b47ccaa62b797a | N2: 19b47c1da257de5a
A3: 22/12/2025 | B3: CARLA TAYLOR t/as CARLORBIZ | C3: Payment sent via Thriday | D3: 3000 | E3: AUD | F3: N-T | G3: Business Transfer | H3: Sent | I3: Thriday | J3: View Email | L3: THRIDAY-489423003-20251222 | M3: 19b47c1da257de5a | N3: 19b47c1da257de5a
A4: 21/12/2025 | B4: Audible.com.au | C4: Audiobook purchase | D4: 24.95 | E4: AUD | F4: GST | G4: Entertainment | H4: Paid | I4: Credit Card | J4: View Email | L4: AUDIBLE-20251221 | M4: 19b413c8fc18e33e | N4: 19b413c8fc18e33e
A5: 20/12/2025 | B5: Golf Network | C5: Invoice CGD-0592593 - Golf Network services | D5: 171.5 | E5: AUD | F5: GST | G5: Recreation | H5: Paid | I5: PayPal | J5: View Email | K5: Invoice-CGD-0592593.pdf | L5: GOLF-CGD-0592593-20251220 | M5: 19b3aa464c636ee4 | N5: 19b3aa464c636ee4
A6: 20/12/2025 | B6: Boxbollen | C6: Family Pack 🎉 (5x) | D6: 159.95 | E6: AUD | F6: GST | G6: Recreation | H6: Confirmed | I6: Mastercard | J6: View Email | L6: BOXBOLLEN-1556501-20251220 | M6: 19b39c903c396335 | N6: 19b39c903c396335
A7: 20/12/2025 | B7: Amazon.com.au | C7: Order 503-9642754-1768633: John Deere toys & household items | D7: 178.45 | E7: AUD | F7: GST | G7: Office | H7: Paid | I7: Credit Card | J7: View Email | L7: AMAZON-503-9642754-1768633 | M7: 19b3a11eb3a2f308 | N7: 19b3a11eb3a2f308
A8: 20/12/2025 | B8: Crazy Golf Deals | C8: PayPal payment - Golf voucher | D8: 171.5 | E8: AUD | F8: GST | G8: Recreation | H8: Paid | I8: PayPal | J8: View Email | L8: PAYPAL-CGD-20251220 | M8: 19b3aa462e01d0d4 | N8: 19b3aa462e01d0d4
A9: 20/12/2025 | B9: Amazon.com.au | C9: arboleaf Mini Massage Gun | D9: 56.99 | E9: AUD | F9: GST | G9: Health | H9: Paid | I9: Credit Card | J9: View Email | L9: AMAZON-503-4005108-5551819 | M9: 19b3b4a90a99b07a | N9: 19b3b4a90a99b07a
A10: 19/12/2025 | B10: CARLA TAYLOR t/as CARLORBIZ | C10: Tax Invoice 2025-00006 - First Nations GP Training | D10: 1100 | E10: AUD | F10: GST | G10: Professional Services | H10: Due 26/12/2025 | I10: Invoice | J10: View Email | K10: Invoice-2025-00006.pdf | L10: CARLORBIZ-2025-00006-20251219 | M10: 19b34d82b42c92d6 | N10: 19b34cd818f44b2c
A11: 19/12/2025 | B11: Railway Corporation | C11: Cloud hosting Hobby plan Dec 2025 | D11: 13.22 | E11: USD | F11: N-T | G11: Software | H11: Paid | I11: Credit Card | J11: View Email | K11: Invoice-BTEKP6WY-0003.pdf | L11: RAILWAY-2512-1006 | M11: 19b39dbd4491fefb | N11: 19b39dbd4491fefb
A12: 19/12/2025 | B12: Starlink | C12: Monthly internet service 12/19-1/18 | D12: 127.5 | E12: AUD | F12: GST | G12: Utilities | H12: Paid | I12: Auto Payment | J12: View Email | K12: INV-DF-AUS-9924557-39911-28.pdf | L12: STARLINK-INV-9924557 | M12: 19b3436114aa8081 | N12: 19b3436114aa8081
A13: 18/12/2025 | B13: Nespresso | C13: Coffee capsules order | D13: 89.5 | E13: AUD | F13: GST | G13: Office | H13: Paid | I13: Credit Card | J13: View Email | K13: Nespresso-Receipt.pdf | L13: NESPRESSO-20251218 | M13: 19b2f906380455b5 | N13: 19b2f906380455b5
A14: 18/12/2025 | B14: IM8 Health | C14: Order IM8-523033 | D14: 156 | E14: AUD | F14: GST | G14: Health | H14: Shipped | I14: Credit Card | J14: View Email | L14: IM8-523033-20251218 | M14: 19b3064f8e0f4375 | N14: 19b3064f8e0f4375
A15: 18/12/2025 | B15: UFS Healthcare | C15: Health insurance renewal notice | D15: 0 | E15: AUD | F15: FRE | G15: Health | H15: Unpaid | I15: Invoice | J15: View Email | K15: UFS-Renewal.pdf | L15: UFS-RENEWAL-20251218 | M15: 19b301bc7dd00020 | N15: 19b301bc7dd00020
A16: 16/12/2025 | B16: Qantas | C16: Flight MEL-SYD EODHBM 05May26 | D16: 285 | E16: AUD | F16: GST | G16: Travel | H16: Paid | I16: Credit Card | J16: View Email | K16: Qantas-EODHBM.pdf | L16: QANTAS-EODHBM-20251216 | M16: 19b26110e5a92539 | N16: 19b26110e5a92539
A17: 16/12/2025 | B17: Marriner Group | C17: A Christmas Carol theatre tickets | D17: 165 | E17: AUD | F17: GST | G17: Entertainment | H17: Confirmed | I17: Credit Card | J17: View Email | L17: MARRINER-20251216 | M17: 19b33b29ba3b7c6b | N17: 19b33b29ba3b7c6b
A18: 14/12/2025 | B18: Dropbox International | C18: Annual subscription payment | D18: 306.9 | E18: AUD | F18: GST | G18: Software | H18: Paid | I18: PayPal | J18: View Email | L18: DROPBOX-20251214 | M18: 19b1c20d4da2867c | N18: 19b1c20d4da2867c
A19: 13/12/2025 | B19: Envato | C19: Elements subscription monthly | D19: 36.3 | E19: USD | F19: N-T | G19: Software | H19: Paid | I19: PayPal | J19: View Email | L19: ENVATO-19757617 | M19: 19b15946e813e289 | N19: 19b15946e813e289
A20: 13/12/2025 | B20: Youly | C20: hubPass monthly subscription | D20: 40 | E20: AUD | F20: GST | G20: Health | H20: Paid | I20: Mastercard | J20: View Email | K20: Receipt-2304-5422.pdf | L20: YOULY-2304-5422 | M20: 19b14f5e2803eda8 | N20: 19b14f5e2803eda8
A21: 12/12/2025 | B21: Consensus | C21: Pro annual subscription | D21: 120 | E21: USD | F21: N-T | G21: Software | H21: Paid | I21: Mastercard | J21: View Email | K21: Receipt-2916-8474.pdf | L21: CONSENSUS-2916-8474 | M21: 19b1100cf6c957c0 | N21: 19b1100cf6c957c0
A22: 11/12/2025 | B22: Adobe Systems | C22: Adobe subscription payment | D22: 31.99 | E22: AUD | F22: GST | G22: Software | H22: Paid | I22: PayPal | J22: View Email | L22: ADOBE-20251211 | M22: 19b0e850ef11dac2 | N22: 19b0e850ef11dac2
A23: 11/12/2025 | B23: LinkedIn Singapore | C23: Premium subscription | D23: 74.99 | E23: AUD | F23: N-T | G23: Software | H23: Paid | I23: PayPal | J23: View Email | L23: LINKEDIN-20251211 | M23: 19b0c2c0ff180607 | N23: 19b0c2c0ff180607
A24: 10/12/2025 | B24: WPManageNinja LLC | C24: Fluent Forms Pro subscription | D24: 129 | E24: USD | F24: N-T | G24: Software | H24: Paid | I24: Mastercard | J24: View Email | K24: Receipt-2509-9830.pdf | L24: RECEIPT:WPManageNinja|2509-9830 | M24: 19b0a3845ae36e9b | N24: 19b0a3845ae36e9b
A25: 10/12/2025 | B25: SuperUltra Inc | C25: SuperWhisper monthly | D25: 8.49 | E25: USD | F25: N-T | G25: Software | H25: Paid | I25: Mastercard | J25: View Email | K25: Receipt-2427-0984.pdf | L25: SUPERULTRA-2427-0984 | M25: 19b0ac41c1122780 | N25: 19b0ac41c1122780
A26: 10/12/2025 | B26: Youly | C26: Mounjaro Kwikpen prescription | D26: 506.73 | E26: AUD | F26: GST | G26: Health | H26: Paid | I26: Mastercard | J26: View Email | L26: YOULY-1475-6148 | M26: 19b069a613ba87a9 | N26: 19b069a613ba87a9
A27: TOTAL | D27: =SUMIF(E2:E26,"AUD",D2:D26)+SUMIF(E2:E26,"USD",D2:D26)*1.5+SUMIF(E29:E41,"AUD",D29:D41)+SUMIF(E29:E41,"USD",D29:D41)*1.5 -> 19805.25
A28: NOVEMBER 2025
A29: 30/11/2025 | B29: Blitzit | C29: Early Access Lifetime subscription | D29: 107.82 | E29: AUD | F29: GST | G29: Software | H29: Paid | I29: Link (Stripe) | J29: View Email | K29: Invoice-85E202B8-20806.pdf | L29: BLITZIT-2271-0797 | M29: 19ad3ac9a9fd1382
A30: 29/11/2025 | B30: Microsoft | C30: Microsoft 365 Business Premium invoice | E30: AUD | F30: GST | G30: Software | H30: Paid | I30: Credit Card | J30: View Email | K30: 82983040133.pdf | L30: MICROSOFT-82983040133 | M30: 19acdaa16369970c
A31: 29/11/2025 | B31: AppSumo | C31: Press Ranger (3) + Black Friday Bundle | D31: 223.63 | E31: USD | F31: N-T | G31: Software | H31: Confirmed | I31: Credit Card | J31: View Email | L31: APPSUMO-20251129 | M31: 19acd1a29355a7ed
A32: 28/11/2025 | B32: WPManageNinja LLC | C32: FluentCommunity Pro Annual License | D32: 119.4 | E32: USD | F32: N-T | G32: Software | H32: Paid | I32: American Express | J32: View Email | K32: Invoice-7L4E3DBB-0001.pdf | L32: WPMN-220193 | M32: 19acc69f6034e08e
A33: 28/11/2025 | B33: StackBlitz Inc | C33: Pro subscription (28 Nov-28 Dec) | D33: 25 | E33: USD | F33: N-T | G33: Software | H33: Paid | I33: Mastercard | J33: View Email | K33: Invoice-OBII2NGP-0001.pdf | L33: STACKBLITZ-2759-4256 | M33: 19aca336ebe5cdf4
A34: 27/11/2025 | B34: Wilson Parking | C34: 50 Lonsdale St parking (28 Nov 09:30-12:30) | D34: 24 | E34: AUD | F34: GST | G34: Travel | H34: Paid | I34: Credit Card | J34: View Email | L34: WILSON-321568235-1 | M34: 19ac54c9cd6be1ab
A35: 27/11/2025 | B35: CARLA TAYLOR t/as CARLORBIZ | C35: Payment sent via Thriday | D35: 6855.43 | E35: AUD | F35: N-T | G35: Business Transfer | H35: Sent | I35: Thriday | J35: View Email | L35: THRIDAY-485689000 | M35: 19ac564a0824022d
A36: 26/11/2025 | B36: Adobe Systems | C36: Acrobat Pro monthly subscription | D36: 37.99 | E36: AUD | F36: GST | G36: Software | H36: Paid | I36: PayPal | J36: View Email | L36: ADOBE-AD04571502904CAU | M36: 19ac0b86e095dc1b
A37: 26/11/2025 | B37: Elementor | C37: Plan upgrade to Ally Standard | E37: AUD | F37: GST | G37: Software | H37: Paid | I37: Credit Card | J37: View Email | K37: INVIL2500294761.pdf | L37: ELEMENTOR-INVIL2500294761 | M37: 19abdcbd83860c7b
A38: 26/11/2025 | B38: Google Australia | C38: Developer Program premium Monthly | D38: 35 | E38: AUD | F38: GST | G38: Software | H38: Paid | I38: American Express | J38: View Email | L38: GOOGLE-GDP-6017 | M38: 19abfad4137b239b
A39: 25/11/2025 | B39: Cloudflare | C39: Cloud services subscription | D39: 30 | E39: USD | F39: N-T | G39: Software | H39: Paid | I39: Mastercard | J39: View Email | L39: CLOUDFLARE-IN-52165555 | M39: 19abae14bda8cfee
A40: 24/11/2025 | B40: Makers Gonna Learn | C40: Special Monthly Member subscription | D40: 27 | E40: USD | F40: N-T | G40: Education | H40: Paid | I40: Mastercard | J40: View Email | K40: Receipt-1829-7427.pdf | L40: MAKERS-1829-7427 | M40: 19ab92fca58739f0
A41: 26/11/2025 | B41: Body Collective Co | C41: Lip care and nail serum products | E41: AUD | F41: GST | G41: Health | H41: Shipped | I41: Credit Card | J41: View Email | L41: BODYCOLLECTIVE-150035 | M41: 19abe9f976c0d688

Sheet Dec 2025
A1: Transaction Date | B1: Vendor/Merchant | C1: Description | D1: Amount | E1: Currency | F1: Category | G1: Payment Method | H1: Status | I1: Source Account | J1: Receipt/Invoice | K1: Reference ID | L1: Email ID | M1: Notes
A2: 22/12/2025 | B2: CARLA TAYLOR t/as CARLORBIZ | C2: Payment sent via Thriday | D2: 5000 | E2: AUD
A3: 22/12/2025 | B3: CARLA TAYLOR t/as CARLORBIZ | C3: Payment sent via Thriday | D3: 3000 | E3: AUD
A4: 21/12/2025 | B4: Audible.com.au | C4: Audiobook purchase | D4: 24.95 | E4: AUD
A5: 20/12/2025 | B5: Golf Network | C5: Invoice CGD-0592593 - Golf Network services | D5: 171.5 | E5: AUD
A6: 20/12/2025 | B6: Boxbollen | C6: Family Pack 🎉 (5x) | D6: 159.95 | E6: AUD
A7: 20/12/2025 | B7: Amazon.com.au | C7: Order 503-9642754-1768633: John Deere toys & household items | D7: 178.45 | E7: AUD
A8: 20/12/2025 | B8: Crazy Golf Deals | C8: PayPal payment - Golf voucher | D8: 171.5 | E8: AUD
A9: 20/12/2025 | B9: Amazon.com.au | C9: arboleaf Mini Massage Gun | D9: 56.99 | E9: AUD
A10: 19/12/2025 | B10: CARLA TAYLOR t/as CARLORBIZ | C10: Tax Invoice 2025-00006 - First Nations GP Training | D10: 1100 | E10: AUD
A11: 19/12/2025 | B11: Railway Corporation | C11: Cloud hosting Hobby plan Dec 2025 | D11: 13.22 | E11: USD
A12: 19/12/2025 | B12: Starlink | C12: Monthly internet service 12/19-1/18 | D12: 127.5 | E12: AUD
A13: 18/12/2025 | B13: Nespresso | C13: Coffee capsules order | D13: 89.5 | E13: AUD
... A26: 10/12/2025 | B26: Youly | C26: Mounjaro Kwikpen prescription | D26: 506.73 | E26: AUD
A27: 2025-12-21 | B27: LANTERNCOVE HOME FRAGRANCES | C27: PayPal - Home fragrance items | D27: 169.95 | E27: AUD | F27: Shopping | G27: PayPal | H27: Paid | I27: carla@carlorbiz.com.au | J27: PayPal Receipt | K27: 19b44371fc7f694d | L27: 19b44371fc7f694d | M27: Lanterncove home products
A28: 2025-12-19 | B28: Crazy Golf Deals Pty Ltd | C28: PayPal - Golf equipment | D28: 171.5 | E28: AUD | F28: Shopping | G28: PayPal | H28: Paid | I28: carla@carlorbiz.com.au | J28: PayPal Receipt CGD-0592593 | K28: 19b3aa464c636ee4 | L28: 19b3aa462e01d0d4 | M28: Golf Network purchase
A29: 2025-12-14 | B29: Dropbox International | C29: PayPal - Cloud storage subscription | D29: 306.9 | E29: AUD | F29: Software | G29: PayPal | H29: Paid | I29: carla@carlorbiz.com.au | J29: PayPal Receipt | K29: 19b1c20d4da2867c | L29: 19b1c20d4da2867c | M29: Dropbox storage renewal
A30: 2025-12-13 | B30: Envato | C30: PayPal - Digital assets subscription | D30: 36.3 | E30: USD | F30: Software | G30: PayPal | H30: Paid | I30: carla@carlorbiz.com.au | J30: PayPal Receipt 19757617 | K30: 19b15946e813e289 | L30: 19b15946e813e289 | M30: Envato Elements
A31: 2025-12-11 | B31: Adobe Systems PTY LT | C31: PayPal - Creative Cloud subscription | D31: 31.99 | E31: AUD | F31: Software | G31: PayPal | H31: Paid | I31: carla@carlorbiz.com.au | J31: PayPal Receipt | K31: 19b0e850ef11dac2 | L31: 19b0e850ef11dac2 | M31: Adobe Creative Cloud
A32: 2025-12-11 | B32: LinkedIn Singapore | C32: PayPal - LinkedIn Premium subscription | D32: 74.99 | E32: AUD | F32: Professional Development | G32: PayPal | H32: Paid | I32: carla@carlorbiz.com.au | J32: PayPal Receipt | K32: 19b0c2c0ff180607 | L32: 19b0c2c0ff180607 | M32: LinkedIn Premium
A33: 2025-12-07 | B33: IMPULSE | C33: PayPal - Brain training subscription | D33: 39.98 | E33: USD | F33: Software | G33: PayPal | H33: Paid | I33: carla@carlorbiz.com.au | J33: PayPal Receipt 1319401254 | K33: 19af86ab309fdb66 | L33: 19af86ab309fdb66 | M33: Brain Impulse app
A34: 2025-12-01 | B34: Microsoft Pty. Limited | C34: PayPal - Microsoft 365 subscription | D34: 33 | E34: AUD | F34: Software | G34: PayPal | H34: Paid | I34: carla@carlorbiz.com.au | J34: PayPal Receipt | K34: 19ad9e5d1e6f780d | L34: 19ad9e5d1e6f780d | M34: Microsoft 365 monthly
A35: 2025-12-12 | B35: Consensus | C35: Annual Pro subscription | D35: 120 | E35: USD | F35: Software | G35: Link | H35: Paid | I35: carla@carlorbiz.com.au | J35: Receipt 2916-8474, Invoice 19AH89WI-0002 | K35: 19b1100cf6c957c0 | L35: 19b1100cf6c957c0 | M35: Consensus Pro plan Dec 11 2025 - Dec 11 2026
A36: 2025-12-10 | B36: SuperUltra, Inc. | C36: Monthly AI transcription subscription | D36: 8.49 | E36: USD | F36: Software | G36: Mastercard | H36: Paid | I36: carla@carlorbiz.com.au | J36: Receipt 2427-0984, Invoice CVPS7G2P-0001 | K36: 19b0ac41c1122780 | L36: 19b0ac41c1122780 | M36: SuperWhisper monthly Dec 10 - Jan 10 2026
A37: 2025-12-10 | B37: YouMind | C37: YouMind Pro annual subscription (50% discount) | D37: 100 | E37: USD | F37: Software | G37: Link | H37: Paid | I37: carla@carlorbiz.com.au | J37: Receipt 2072-6216, Invoice KM4MCEX5-0001 | K37: 19b053b9fa8b72fb | L37: 19b053b9fa8b72fb | M37: YouMind Pro Dec 10 2025 - Dec 10 2026
B100: TOTAL | D100: =SUMIF(E:E,"AUD",D:D)+SUMIF(E:E,"USD",D:D)*1.5 -> 13352.95

Sheet Nov 2025
A1: please continue | B1: Vendor/Merchant | C1: Description | D1: Amount | E1: Currency | F1: Category | G1: Payment Method | H1: Status | I1: Source Account | J1: Receipt/Invoice | K1: Reference ID | L1: Email ID | M1: Notes
A2: 30/11/2025 | B2: Blitzit | C2: Early Access Lifetime subscription | D2: 107.82 | E2: AUD
A3: 29/11/2025 | B3: Microsoft | C3: Microsoft 365 Business Premium invoice | E3: AUD
A4: 29/11/2025 | B4: AppSumo | C4: Press Ranger (3) + Black Friday Bundle | D4: 223.63 | E4: USD
A5: 28/11/2025 | B5: WPManageNinja LLC | C5: FluentCommunity Pro Annual License | D5: 119.4 | E5: USD
A6: 28/11/2025 | B6: StackBlitz Inc | C6: Pro subscription (28 Nov-28 Dec) | D6: 25 | E6: USD
A7: 27/11/2025 | B7: Wilson Parking | C7: 50 Lonsdale St parking (28 Nov 09:30-12:30) | D7: 24 | E7: AUD
A8: 27/11/2025 | B8: CARLA TAYLOR t/as CARLORBIZ | C8: Payment sent via Thriday | D8: 6855.43 | E8: AUD
A9: 26/11/2025 | B9: Adobe Systems | C9: Acrobat Pro monthly subscription | D9: 37.99 | E9: AUD
A10: 26/11/2025 | B10: Elementor | C10: Plan upgrade to Ally Standard | E10: AUD
A11: 26/11/2025 | B11: Google Australia | C11: Developer Program premium Monthly | D11: 35 | E11: AUD
A12: 25/11/2025 | B12: Cloudflare | C12: Cloud services subscription | D12: 30 | E12: USD
A13: 24/11/2025 | B13: Makers Gonna Learn | C13: Special Monthly Member subscription | D13: 27 | E13: USD
A14: 26/11/2025 | B14: Body Collective Co | C14: Lip care and nail serum products | E14: AUD
A15: 2025-11-21 | B15: Evopaper LLC | C15: PayPal - Digital paper/notebook tool | D15: 14.97 | E15: USD | F15: Software | G15: PayPal | H15: Paid | I15: carla@carlorbiz.com.au | J15: PayPal Receipt 286de768-06fa-4d45-a3e9 | K15: 19aa4a0c3ad18a0b | L15: 19aa4a0c3ad18a0b | M15: Evopaper subscription
A16: 2025-11-12 | B16: ALDImobile | C16: PayPal - Mobile service payment | D16: 365 | E16: AUD | F16: Utilities | G16: PayPal | H16: Paid | I16: carla@carlorbiz.com.au | J16: PayPal Receipt 225294018 | K16: 19a76a69823e3dd8 | L16: 19a76a69823e3dd8 | M16: ALDImobile 12-month plan
A17: 2025-11-11 | B17: Adobe Systems PTY LT | C17: PayPal - Creative Cloud subscription | D17: 31.99 | E17: AUD | F17: Software | G17: PayPal | H17: Paid | I17: carla@carlorbiz.com.au | J17: PayPal Receipt | K17: 19a73d3191c80cfc | L17: 19a73d3191c80cfc | M17: Adobe Creative Cloud monthly
A18: 2025-11-11 | B18: LinkedIn Singapore | C18: PayPal - LinkedIn Premium subscription | D18: 74.99 | E18: AUD | F18: Professional Development | G18: PayPal | H18: Paid | I18: carla@carlorbiz.com.au | J18: PayPal Receipt | K18: 19a71ad26d7c439f | L18: 19a71ad26d7c439f | M18: LinkedIn Premium monthly
A19: 2025-11-09 | B19: IMPULSE | C19: PayPal - Brain training subscription | D19: 39.98 | E19: USD | F19: Software | G19: PayPal | H19: Paid | I19: carla@carlorbiz.com.au | J19: PayPal Receipt 1288089929 | K19: 19a6838cb9bd965c | L19: 19a6838cb9bd965c | M19: Brain Impulse app monthly
A20: 2025-11-07 | B20: WellSource Ltd. | C20: PayPal - Speech Logger Pro plan | D20: 60 | E20: USD | F20: Software | G20: PayPal | H20: Paid | I20: carla@carlorbiz.com.au | J20: PayPal Receipt | K20: 19a5ca0fcbdd09dd | L20: 19a5ca0fcbdd09dd | M20: Speech Logger premium
A21: 2025-11-07 | B21: WellSource Ltd. | C21: PayPal - Speech Logger additional credits | D21: 22.8 | E21: USD | F21: Software | G21: PayPal | H21: Paid | I21: carla@carlorbiz.com.au | J21: PayPal Receipt | K21: 19a5c93ff390bbd3 | L21: 19a5c93ff390bbd3 | M21: Speech Logger credits purchase 1
A22: 2025-11-07 | B22: WellSource Ltd. | C22: PayPal - Speech Logger additional credits | D22: 22.8 | E22: USD | F22: Software | G22: PayPal | H22: Paid | I22: carla@carlorbiz.com.au | J22: PayPal Receipt | K22: 19a5c93a89d1a994 | L22: 19a5c93a89d1a994 | M22: Speech Logger credits purchase 2
A23: 2025-11-01 | B23: Microsoft Pty. Limited | C23: PayPal - Microsoft 365 subscription | D23: 33 | E23: AUD | F23: Software | G23: PayPal | H23: Paid | I23: carla@carlorbiz.com.au | J23: PayPal Receipt | K23: 19a4096a7aced755 | L23: 19a4096a7aced755 | M23: Microsoft 365 monthly
A24: 2025-11-07 | B24: Cerebras Systems Inc. | C24: Purchased AI inference credits | D24: 25 | E24: USD | F24: Software | G24: American Express | H24: Paid | I24: carla@carlorbiz.com.au | J24: Receipt 2058-1136, Invoice A1LHF4ZI-0001 | K24: 19a5e987c39664ef | L24: 19a5e987c39664ef | M24: 2500 credits at $0.01 each
A25: 2025-11-02 | B25: xAI API | C25: Invoice for API usage November 2025 | D25: 0.22 | E25: USD | F25: Software | G25: Prepaid Tokens | H25: Paid | I25: carla@carlorbiz.com.au | J25: Invoice 668-918-905-015 | K25: 19ae174a9698cc41 | L25: 19ae174a9698cc41 | M25: Prepaid tokens consumed for Nov 2025
A26: 2025-11-04 | B26: Team Thrive No 2 Pty Ltd | C26: Thriday financial platform subscription | D26: 175 | E26: AUD | F26: Software | G26: Link | H26: Paid | I26: carla@carlorbiz.com.au | J26: Receipt 1054-1911 | K26: 19a4e4c2168bb9c8 | L26: 19a4e4c2168bb9c8 | M26: Team Thrive Thriday subscription
A27: 2025-11-18 | B27: JB Hi-Fi | C27: Order #JB-23528949 - reMarkable Marker for reMarkable 2 | D27: 124.99 | E27: AUD | F27: Office | G27: Credit Card | H27: Ordered | I27: carlorbiz@gmail.com | J27: Tax Invoice JB-23528949 | K27: JB-23528949 | M27: Amount in PDF attachment - needs extraction
A28: 2025-11-12 | B28: BMW ConnectedDrive | C28: Connected Package Professional subscription (12 months, BMW X4) | D28: 179 | E28: AUD | F28: Utilities | G28: Auto Payment | H28: Paid | I28: carlorbiz@gmail.com | J28: Invoice CDI0093205 | K28: CDI0093205 | L28: 19a7792ad8e0a85d | M28: Annual subscription 12.11.2025 - 12.11.2026, VIN WBAXX120600X21689
A29: 2025-11-12 | B29: AppleCare+ | C29: AppleCare+ monthly renewal (technical support) | D29: 11.99 | E29: AUD | F29: Software | G29: Apple Account | H29: Paid | I29: carlorbiz@gmail.com | J29: Apple Tax Invoice | M29: Monthly recurring - check Apple email for exact amount
B100: TOTAL | D100: =SUMIF(E:E,"AUD",D:D)+SUMIF(E:E,"USD",D:D)*1.5 -> 8972.4

Sheet Oct 2025
A1: Transaction Date | B1: Vendor/Merchant | C1: Description | D1: Amount | E1: Currency | F1: Category | G1: Payment Method | H1: Status | I1: Source Account | J1: Receipt/Invoice | K1: Reference ID | L1: Email ID | M1: Notes
A2: 31/10/2025 | B2: PayPal (Kristy Amos Photography) | C2: Photography services payment | D2: 1950 | E2: AUD | F2: Professional Services | G2: PayPal | H2: Paid | I2: Gmail | J2: Receipt | K2: 69V880447P689693X | L2: 19a35387f75fd17a
A3: 30/10/2025 | B3: Kristy Amos Photography | C3: Photography services invoice | D3: 1950 | E3: AUD | F3: Professional Services | G3: Invoice | H3: Paid | I3: Gmail | J3: Invoice-20251017.pdf | K3: 4483996 | L3: 19a3538756ccdcf0 | M3: ESTIMATED - Verify from source (HIGH PRIORITY)
A4: 30/10/2025 | B4: Freemius Inc | C4: ZenCommunity Pro plugin | D4: 199 | E4: USD | F4: Software | G4: PayPal | H4: Paid | I4: Gmail | J4: Receipt | K4: 84U3708858122233D | L4: 19a319a589118020
A5: 29/10/2025 | B5: Kodezen Limited | C5: ZenCommunity Pro LTD plugin | D5: 199 | E5: USD | F5: Software | G5: PayPal | H5: Paid | I5: Gmail | J5: Invoice 1807251 | K5: 1807251 | L5: 19a319a29cccc684
A6: 29/10/2025 | B6: Microsoft | C6: Microsoft 365 Business Standard October | D6: 179 | E6: AUD | F6: Software | G6: Credit Card | H6: Paid | I6: Gmail | J6: Invoice 82938124163 | K6: 82938124163 | L6: 19a2dc790bff711c | M6: ESTIMATED - Verify from source
A7: 28/10/2025 | B7: Microsoft | C7: Microsoft 365 Business Premium October | D7: 179 | E7: AUD | F7: Software | G7: Credit Card | H7: Paid | I7: Gmail | J7: Invoice 82936845638 | K7: 82936845638 | L7: 19a28ab71973cf3d | M7: ESTIMATED - Verify from source
A8: 24/10/2025 | B8: Team Thrive No 2 Pty Ltd (Thriday) | C8: BAS + Tax Plan - Annual | D8: 1190 | E8: AUD | F8: Professional Services | G8: Link | H8: Paid | I8: Gmail | J8: Receipt 2512-5510 | K8: NGH3TAMW-0001 | L8: 19a1363fd6f3af12
A9: 19/10/2025 | B9: Railway Corporation | C9: Hobby plan subscription | D9: 5 | E9: USD | F9: Software | G9: American Express | H9: Paid | I9: Gmail | J9: Receipt 2862-6109 | K9: BTEKP6WY-0001 | L9: 199ff7f37780348d
A10: 13/10/2025 | B10: Youly | C10: hubPass | D10: 40 | E10: AUD | F10: Office | G10: Mastercard | H10: Paid | I10: Gmail | J10: Receipt 2551-6961 | K10: 7E1FCEC1-0014 | L10: 199dad15aff60af4
A11: 08/10/2025 | B11: Hume AI | C11: Creator Plan subscription | D11: 14 | E11: USD | F11: Software | G11: American Express | H11: Paid | I11: Gmail | J11: Receipt 2183-6369 | K11: TS5YODPN-0003 | L11: 199c3d146ceb55d3
A12: 01/10/2025 | B12: Speechify Inc. | C12: Speechify AI Studio Pro | D12: 595 | E12: AUD | F12: Software | G12: American Express | H12: Paid | I12: Gmail | J12: Receipt 2821-2852 | K12: XGLWR541-0003 | L12: 199a4b8f6e8c0000
A13: 2025-10-18 | B13: Wondershare | C13: PayPal - Video editing software | D13: 43.95 | E13: USD | F13: Software | G13: PayPal | H13: Paid | I13: carla@carlorbiz.com.au | J13: PayPal Receipt | K13: 199f4c97ef1469b9 | L13: 199f4c97ef1469b9 | M13: Wondershare Filmora
A14: 2025-10-13 | B14: Envato | C14: Envato Elements subscription | D14: 36.3 | E14: USD | F14: Software | G14: PayPal | H14: Paid | I14: carla@carlorbiz.com.au | J14: PayPal Receipt | M14: Monthly subscription - Added during audit
A15: 2025-10-15 | B15: Hypnopulse UAB | C15: PayPal - Hypnosis/meditation app subscription | D15: 102.9 | E15: AUD | F15: Health & Wellness | G15: PayPal | H15: Paid | I15: carla@carlorbiz.com.au | J15: PayPal Receipt | K15: 199e2d3b5156da64 | L15: 199e2d3b5156da64 | M15: Hypnopulse subscription
A16: 2025-10-14 | B16: Zapier, Inc. | C16: PayPal - Workflow automation subscription | D16: 377.89 | E16: AUD | F16: Software | G16: PayPal | H16: Paid | I16: carla@carlorbiz.com.au | J16: PayPal Receipt 0199e079-1bfd-42e7-ba12 | K16: 199e0797350321f4 | L16: 199e0797350321f4 | M16: Zapier automation platform
A17: 2025-10-12 | B17: IMPULSE | C17: PayPal - Brain training subscription | D17: 39.98 | E17: USD | F17: Software | G17: PayPal | H17: Paid | I17: carla@carlorbiz.com.au | J17: PayPal Receipt 1253865871 | K17: 199d806d99c5e0e5 | L17: 199d806d99c5e0e5 | M17: Brain Impulse app monthly
A18: 2025-10-11 | B18: LinkedIn Singapore | C18: PayPal - LinkedIn Premium subscription | D18: 74.99 | E18: AUD | F18: Professional Development | G18: PayPal | H18: Paid | I18: carla@carlorbiz.com.au | J18: PayPal Receipt | K18: 199d207d015ae9a1 | L18: 199d207d015ae9a1 | M18: LinkedIn Premium monthly
A19: 2025-10-23 | B19: Team Thrive No 2 Pty Ltd | C19: Thriday financial platform subscription | D19: 175 | E19: AUD | F19: Software | G19: Link | H19: Paid | I19: carla@carlorbiz.com.au | J19: Receipt 2512-5510, Invoice | K19: 19a1363fd6f3af12 | L19: 19a1363fd6f3af12 | M19: Team Thrive Thriday Oct 23
A20: 2025-10-03 | B20: xAI API | C20: Invoice for API usage October 2025 | D20: 0.22 | E20: USD | F20: Software | G20: Prepaid Tokens | H20: Paid | I20: carla@carlorbiz.com.au | J20: Invoice 668-918-905-015 | K20: 19a4a73b91505d38 | L20: 19a4a73b91505d38 | M20: xAI API usage Oct 2025
A21: 2025-10-26 | B21: Coral Case Pty Ltd | C21: Google Pixel 10 Pro Lifeproof Waterproof Case - Order #12678 | D21: 101.4 | E21: AUD | F21: Shopping | G21: Stripe | H21: Paid | I21: carlorbiz@gmail.com | J21: Receipt #1237-6644 | K21: Order #12678 | L21: 19a207c39e706752 | M21: From carlorbiz@gmail.com
A22: 2025-10-25 | B22: Apple | C22: Grok SuperGrok (Monthly) subscription | D22: 50 | E22: USD | F22: Software | G22: Apple Account | H22: Paid | I22: carlorbiz@gmail.com | J22: Tax Invoice | K22: Order MM275QTHVY, Doc 702040030823 | L22: 19a1a8a77706dd7a | M22: From carlorbiz@gmail.com; Renews Nov 25
A23: 2025-10-24 | B23: Apple | C23: Apple TV+ Monthly subscription | D23: 15.99 | E23: USD | F23: Entertainment | G23: Apple Account | H23: Paid | I23: carlorbiz@gmail.com | J23: Tax Invoice | K23: Order MM275LMM1B, Doc 788039605502 | L23: 19a1546d53283035 | M23: From carlorbiz@gmail.com; Renews Nov 24
A24: 2025-10-24 | B24: Apple | C24: Manus AI Manus Pro - Monthly subscription | D24: 299 | E24: USD | F24: Software | G24: Apple Account | H24: Paid | I24: carlorbiz@gmail.com | J24: Tax Invoice | K24: Order MM275L1FJG, Doc 718039446046 | L24: 19a13e56cbe9a13f | M24: From carlorbiz@gmail.com; Renews Nov 24
A25: 2025-10-22 | B25: Telstra | C25: Apple iPhone 16e 128GB Black - Device payout (5 payments remaining) | D25: 416.25 | E25: AUD | F25: Utilities | G25: Auto Payment | H25: Paid | I25: carlorbiz@gmail.com | J25: Tax Invoice TTI20159401206 | K25: TTI20159401206 | L25: 19a0a6fbbd0acd1b | M25: From carlorbiz@gmail.com; Due Nov 5
A26: 2025-10-14 | B26: Ambulance Victoria | C26: Single Membership - 1 Year renewal | D26: 54.97 | E26: AUD | F26: Health | G26: Direct Debit | H26: Paid | I26: carlorbiz@gmail.com | J26: Receipt #23411469 | K26: Member #23411469 | L26: 199e297d4f87d101 | M26: From carlorbiz@gmail.com; Expires Oct 14, 2026
A27: 2025-10-14 | B27: Apple | C27: AppleCare+ Technical support & accidental damage coverage Monthly | D27: Amount pending | E27: USD | F27: Software | G27: Apple Account | H27: Paid | I27: carlorbiz@gmail.com | J27: Tax Invoice | K27: Order MM274H6XWL, Doc 814034475079 | L27: 199e0dfb7fa74a66 | M27: From carlorbiz@gmail.com; Renewal notice
A28: 2025-10-12 | B28: Apple | C28: AppleCare+ Technical support & accidental damage coverage Monthly | D28: Amount pending | E28: USD | F28: Software | G28: Apple Account | H28: Paid | I28: carlorbiz@gmail.com | J28: Tax Invoice | K28: Order MM2779N3XF, Doc 770048020029 | L28: 19a7661bd19ac99b | M28: From carlorbiz@gmail.com; Nov 12 renewal
A29: 2025-10-17 | B29: Wondershare | C29: MirrorGo Subscription Renewal | D29: 43.95 | E29: USD | F29: Software | G29: Auto Payment | H29: Confirmed | I29: opalcarabina@gmail.com | J29: Payment reminder email | K29: Wondershare MirrorGo | L29: 199a7efb533339af | M29: Annual subscription renewal Oct 17, 2025
B101: TOTAL | D101: =SUMIF(E:E,"AUD",D:D)+SUMIF(E:E,"USD",D:D)*1.5 -> 8805.985

Sheet Sep 2025
A1: Transaction Date | B1: Vendor/Merchant | C1: Description | D1: Amount | E1: Currency | F1: Category | G1: Payment Method | H1: Status | I1: Source Account | J1: Receipt/Invoice | K1: Reference ID | L1: Email ID | M1: Notes
A2: 27/09/2025 | B2: DocsAutomator UG | C2: DocsAutomator 200 | D2: 180 | E2: USD | F2: Software | G2: Mastercard | H2: Paid | I2: Gmail | J2: Receipt 2011-0172 | K2: A8F73B7F-6731 | L2: 1998a86a74094564
A3: 17/09/2025 | B3: Manus AI | C3: 19,900 Manus credits | D3: 199 | E3: USD | F3: Software | G3: Link | H3: Paid | I3: Gmail | J3: Receipt 2846-7525 | K3: 14MVCWS2-0001 | L3: 19954f2f09faa373
A4: 13/09/2025 | B4: Youly | C4: hubPass | D4: 40 | E4: AUD | F4: Office | G4: Mastercard | H4: Paid | I4: Gmail | J4: Receipt 2829-8504 | K4: 7E1FCEC1-0013 | L4: 199404f8719985d1
A5: 08/09/2025 | B5: Hume AI | C5: Creator Plan | D5: 14 | E5: USD | F5: Software | G5: American Express | H5: Paid | I5: Gmail | J5: Receipt 2991-3292 | K5: TS5YODPN-0002 | L5: 19929516f8632e04
A6: 01/09/2025 | B6: Speechify Inc. | C6: Speechify AI Studio Pro | D6: 595 | E6: AUD | F6: Software | G6: American Express | H6: Paid | I6: Gmail | J6: Receipt 2821-2852 | K6: XGLWR541-0002 | L6: 1.99e+15
A7: 2025-09-27 | B7: Macpac Retail Pty Li | C7: PayPal - Outdoor clothing/gear purchase | D7: 174.99 | E7: AUD | F7: Shopping | G7: PayPal | H7: Paid | I7: carla@carlorbiz.com.au | J7: PayPal Receipt | K7: 1.9988981e+15 | L7: 1.9988981e+15 | M7: Macpac outdoor gear
A8: 2025-09-25 | B8: ANTHEA CRAWFORD (AUS) | C8: PayPal - Clothing purchase | D8: 324 | E8: AUD | F8: Shopping | G8: PayPal | H8: Paid | I8: carla@carlorbiz.com.au | J8: PayPal Receipt | K8: 1997e0def3edf2da | L8: 1997e0def3edf2da | M8: Anthea Crawford fashion
A9: 2025-09-23 | B9: Google Payment Austr | C9: PayPal - Google service payment | D9: 16.99 | E9: AUD | F9: Software | G9: PayPal | H9: Paid | I9: carla@carlorbiz.com.au | J9: PayPal Receipt | K9: 1997466f244d70f2 | L9: 1997466f244d70f2 | M9: Google service
A10: 2025-09-14 | B10: Menesko, UAB | C10: PayPal - Health/nutrition app subscription | D10: 151 | E10: AUD | F10: Health & Wellness | G10: PayPal | H10: Paid | I10: carla@carlorbiz.com.au | J10: PayPal Receipt | K10: 19947e67c64d95d3 | L10: 19947e67c64d95d3 | M10: DigestiPlan subscription
A11: 2025-09-14 | B11: IMPULSE | C11: PayPal - Brain training subscription | D11: 39.98 | E11: USD | F11: Software | G11: PayPal | H11: Paid | I11: carla@carlorbiz.com.au | J11: PayPal Receipt | K11: 19947d47797e7b44 | L11: 19947d47797e7b44 | M11: Brain Impulse app monthly
A12: 2025-09-13 | B12: Envato | C12: PayPal - Digital assets subscription | D12: 36.3 | E12: USD | F12: Software | G12: PayPal | H12: Paid | I12: carla@carlorbiz.com.au | J12: PayPal Receipt 18917656 | K12: 19940f1ef3779541 | L12: 19940f1ef3779541 | M12: Envato Elements
A13: 2025-09-11 | B13: Adobe Systems PTY LT | C13: PayPal - Creative Cloud subscription | D13: 31.99 | E13: AUD | F13: Software | G13: PayPal | H13: Paid | I13: carla@carlorbiz.com.au | J13: PayPal Receipt | K13: 1993924c070dde05 | L13: 1993924c070dde05 | M13: Adobe Creative Cloud monthly
A14: 2025-09-11 | B14: LinkedIn Singapore | C14: PayPal - LinkedIn Premium subscription | D14: 74.99 | E14: AUD | F14: Professional Development | G14: PayPal | H14: Paid | I14: carla@carlorbiz.com.au | J14: PayPal Receipt | K14: 199378951709fe18 | L14: 199378951709fe18 | M14: LinkedIn Premium monthly
A15: 2025-09-11 | B15: Mountain Warehouse A | C15: PayPal - Outdoor clothing purchase | D15: 295.94 | E15: AUD | F15: Shopping | G15: PayPal | H15: Paid | I15: carla@carlorbiz.com.au | J15: PayPal Receipt | K15: 1993708c2b0203f6 | L15: 1993708c2b0203f6 | M15: Mountain Warehouse order
A16: 2025-09-05 | B16: Cleverbridge GmbH | C16: PayPal - Software purchase | D16: 302.49 | E16: AUD | F16: Software | G16: PayPal | H16: Paid | I16: carla@carlorbiz.com.au | J16: PayPal Receipt | K16: 199179088988a8f0 | L16: 199179088988a8f0 | M16: Cleverbridge software
A17: 2025-09-01 | B17: Microsoft Pty. Limited | C17: PayPal - Microsoft 365 subscription | D17: 33 | E17: AUD | F17: Software | G17: PayPal | H17: Paid | I17: carla@carlorbiz.com.au | J17: PayPal Receipt | K17: 1990451152e71f7b | L17: 1990451152e71f7b | M17: Microsoft 365 monthly
A18: 2025-09-25 | B18: xAI, LLC | C18: Prepaid tokens purchase | D18: 100 | E18: USD | F18: Software | G18: Link | H18: Paid | I18: carla@carlorbiz.com.au | J18: Receipt 1588-5633 | K18: 199808dafb2b2659 | L18: 199808dafb2b2659 | M18: xAI prepaid tokens $100
A19: 2025-09-29 | B19: Dyson | C19: WashG1 ANZ Bk/Bu - Dyson WashG1 Wet Floor Cleaner | D19: 449 | E19: AUD | F19: Shopping | G19: Credit Card | H19: Paid | I19: carlorbiz@gmail.com | J19: Order 6327420109 | K19: 6327420109 | L19: 19992f1ce6f4a7c8 | M19: Subtotal $408.18, GST $40.82, Shipping $0.00
A20: 2025-09-25 | B20: Apple | C20: Grok SuperGrok monthly subscription | D20: 50 | E20: USD | F20: Software | G20: Apple Account | H20: Paid | I20: carlorbiz@gmail.com | J20: Apple Tax Invoice | M20: Renews Dec 25, 2025
A21: 2025-09-24 | B21: Apple | C21: Manus AI Manus Pro monthly subscription | D21: 299 | E21: USD | F21: Software | G21: Apple Account | H21: Paid | I21: carlorbiz@gmail.com | J21: Apple Tax Invoice | M21: Renews Dec 24, 2025
A22: 2025-09-24 | B22: Manus AI | C22: Manus AI adjustment/credit | D22: -13.77 | E22: USD | F22: Software | G22: Apple Account | H22: Paid | I22: carlorbiz@gmail.com | J22: Apple Adjustment Note | M22: Account adjustment - credit applied
A23: 2025-09-24 | B23: Apple | C23: Apple TV+ monthly subscription | D23: 12.99 | E23: USD | F23: Entertainment | G23: Apple Account | H23: Paid | I23: carlorbiz@gmail.com | J23: Apple Tax Invoice | M23: Renews Dec 24, 2025
A24: 2025-09-19 | B24: ChatGPT | C24: ChatGPT Plus Annual subscription | D24: 300 | E24: USD | F24: Software | G24: Apple Account | H24: Paid | I24: carlorbiz@gmail.com | J24: Apple Tax Invoice | M24: Annual subscription via Apple
A25: 2025-09-11 | B25: AppleCare+ | C25: AppleCare+ monthly renewal | D25: 12.49 | E25: AUD | F25: Software | G25: Apple Account | H25: Paid | I25: carlorbiz@gmail.com | J25: Apple Tax Invoice | M25: Monthly recurring - check Apple email for exact amount
A26: 2025-09-04 | B26: Pet Circle | C26: Auto Delivery Order #82795886 - Adult Medium Breed Dry Dog Food | D26: 125.39 | E26: AUD | F26: Pet Supplies | G26: PayPal | H26: Delivered | I26: opalcarabina@gmail.com | J26: Order confirmation email | K26: #82795886 | L26: 199133db8ade38e8 | M26: Auto Delivery - delivered Sept 4, 2025
A27: 2025-09-06 | B27: AgeMate | C27: Daily Longevity Blend Double Subscription | D27: 149 | E27: AUD | F27: Health & Wellness | G27: Subscription | H27: Confirmed | I27: opalcarabina@gmail.com | J27: Order confirmation email | K27: AM4627293 | L27: 1991d47611c2bc2a | M27: Renewal order confirmed Sept 6, 2025
B100: TOTAL | D100: =SUMIF(E:E,"AUD",D:D)+SUMIF(E:E,"USD",D:D)*1.5 -> 4602.52

Sheet Aug 2025
A1: Transaction Date | B1: Vendor/Merchant | C1: Description | D1: Amount | E1: Currency | F1: Category | G1: Payment Method | H1: Status | I1: Source Account | J1: Receipt/Invoice | K1: Reference ID | L1: Email ID | M1: Notes
A2: 29/08/2025 | B2: Gamma | C2: Pro plan upgrade (net of credit) | D2: 107.58 | E2: USD | F2: Software | G2: Mastercard | H2: Paid | I2: Gmail | J2: Receipt 2679-8763 | K2: KFUVBFFB-0002 | L2: 198f519f570ac752
A3: 28/08/2025 | B3: MainFunc PTE. LTD. | C3: Genspark Credits Pack | D3: 22 | E3: USD | F3: Software | G3: Link | H3: Paid | I3: Gmail | J3: Receipt 2031-8966 | K3: 5KYQPPPJ-0002 | L3: 198f44a2e5784bc2
A4: 25/08/2025 | B4: Anthropic, PBC | C4: One-time credit purchase | D4: 5.5 | E4: USD | F4: Software | G4: Link | H4: Paid | I4: Gmail | J4: Receipt 2612-0775-6745 | K4: BHFDLUOA-0001 | L4: 198e47d34570c577
A5: 13/08/2025 | B5: Youly | C5: hubPass | D5: 40 | E5: AUD | F5: Office | G5: Mastercard | H5: Paid | I5: Gmail | J5: Receipt 2689-1515 | K5: 7E1FCEC1-0012 | L5: 198a0aba1fd74b81
A6: 11/08/2025 | B6: Elementor | C6: Invoice for order | D6: 99 | E6: AUD | F6: Software | G6: Credit Card | H6: Paid | I6: Gmail | J6: Invoice ZINV01008780 | K6: INVIL2500205463 | L6: 198997f7399e96d9 | M6: ESTIMATED - Verify from source
A7: 08/08/2025 | B7: Hume AI | C7: Creator Plan | D7: 14 | E7: USD | F7: Software | G7: American Express | H7: Paid | I7: Gmail | J7: Receipt 2724-5334 | K7: TS5YODPN-0001 | L7: 1988972573f462c2
A8: 04/08/2025 | B8: Speechify Inc. | C8: Speechify AI Studio Pro | D8: 595 | E8: AUD | F8: Software | G8: American Express | H8: Paid | I8: Gmail | J8: Receipt 2821-2852 | K8: XGLWR541-0002 | L8: 19872e79c1940d69
A9: 01/08/2025 | B9: Speechify Inc. | C9: Speechify AI Studio Pro | D9: 595 | E9: AUD | F9: Software | G9: American Express | H9: Paid | I9: Gmail | J9: Receipt 2821-2852 | K9: XGLWR541-0001 | L9: 1.985e+15
A10: 2025-08-30 | B10: COURSIV ELEARNING | C10: PayPal - Online course platform | D10: 87.99 | E10: USD | F10: Education | G10: PayPal | H10: Paid | I10: carla@carlorbiz.com.au | J10: PayPal Receipt | K10: 198fa508205b391c | L10: 198fa508205b391c | M10: Coursiv eLearning platform
A11: 2025-08-28 | B11: Pet Circle | C11: PayPal - Pet supplies purchase | D11: 125.39 | E11: AUD | F11: Shopping | G11: PayPal | H11: Paid | I11: carla@carlorbiz.com.au | J11: PayPal Receipt | K11: 198ebf3e566829fe | L11: 198ebf3e566829fe | M11: Pet Circle order
A12: 2025-08-26 | B12: Qolaba LLC | C12: PayPal - AI tool subscription | D12: 11 | E12: USD | F12: Software | G12: PayPal | H12: Paid | I12: carla@carlorbiz.com.au | J12: PayPal Receipt | K12: 198e4ba5e5810895 | L12: 198e4ba5e5810895 | M12: Qolaba AI service
A13: 2025-08-17 | B13: IMPULSE | C13: PayPal - Brain training subscription | D13: 19.99 | E13: USD | F13: Software | G13: PayPal | H13: Paid | I13: carla@carlorbiz.com.au | J13: PayPal Receipt 1186146918 | K13: 198b7a245812a0b3 | L13: 198b7a245812a0b3 | M13: Brain Impulse app monthly
A14: 2025-08-13 | B14: Envato | C14: PayPal - Digital assets subscription | D14: 36.3 | E14: USD | F14: Software | G14: PayPal | H14: Paid | I14: carla@carlorbiz.com.au | J14: PayPal Receipt 18644156 | K14: 198a14cb555d1c0d | L14: 198a14cb555d1c0d | M14: Envato Elements
A15: 2025-08-12 | B15: Canva Pty Limited | C15: PayPal - Design platform subscription | D15: 165 | E15: AUD | F15: Software | G15: PayPal | H15: Paid | I15: carla@carlorbiz.com.au | J15: PayPal Receipt | K15: 1989c53b4a3b2e8a | L15: 1989c53b4a3b2e8a | M15: Canva Pro subscription
A16: 2025-08-11 | B16: Adobe Systems PTY LT | C16: PayPal - Creative Cloud subscription | D16: 31.99 | E16: AUD | F16: Software | G16: PayPal | H16: Paid | I16: carla@carlorbiz.com.au | J16: PayPal Receipt | K16: 19899b7ad44f3651 | L16: 19899b7ad44f3651 | M16: Adobe Creative Cloud monthly
A17: 2025-08-11 | B17: LinkedIn Singapore | C17: PayPal - LinkedIn Premium subscription | D17: 37.49 | E17: AUD | F17: Professional Development | G17: PayPal | H17: Paid | I17: carla@carlorbiz.com.au | J17: PayPal Receipt | K17: 19897e3e9f7a0304 | L17: 19897e3e9f7a0304 | M17: LinkedIn Premium monthly
A18: 2025-08-07 | B18: Pet Circle | C18: PayPal - Pet supplies purchase | D18: 152.93 | E18: AUD | F18: Shopping | G18: PayPal | H18: Paid | I18: carla@carlorbiz.com.au | J18: PayPal Receipt | K18: 1987fbc05145e547 | L18: 1987fbc05145e547 | M18: Pet Circle second order
A19: 2025-08-05 | B19: Actitech Limited | C19: PayPal - Health & fitness app | D19: 39.99 | E19: AUD | F19: Health & Wellness | G19: PayPal | H19: Paid | I19: carla@carlorbiz.com.au | J19: PayPal Receipt | K19: 198770ed7f2a3004 | L19: 198770ed7f2a3004 | M19: Health fitness subscription
A20: 2025-08-01 | B20: Microsoft Pty. Limited | C20: PayPal - Microsoft 365 subscription | D20: 33 | E20: AUD | F20: Software | G20: PayPal | H20: Paid | I20: carla@carlorbiz.com.au | J20: PayPal Receipt | K20: 198651897b3502c6 | L20: 198651897b3502c6 | M20: Microsoft 365 monthly
A21: 2025-08-20 | B21: ChatGPT | C21: ChatGPT Plus Monthly subscription | D21: 29.99 | E21: USD | F21: Software | G21: Apple Account | H21: Paid | I21: carlorbiz@gmail.com | J21: Apple Tax Invoice | M21: Monthly subscription via Apple - switched to Annual in September
A22: 2025-08-12 | B22: AppleCare+ | C22: AppleCare+ monthly renewal | D22: 12.49 | E22: AUD | F22: Software | G22: Apple Account | H22: Paid | I22: carlorbiz@gmail.com | J22: Apple Tax Invoice | M22: Monthly recurring - check Apple email for exact amount
A23: 2025-08-24 | B23: Manus AI | C23: Manus AI Manus Plus monthly subscription | D23: 59 | E23: USD | F23: Software | G23: Apple Account | H23: Paid | I23: carlorbiz@gmail.com | J23: Apple Tax Invoice | M23: Monthly subscription via Apple - upgraded to Manus Pro in September
A24: 2025-08-27 | B24: Pet Circle | C24: Auto Delivery Order #82795886 - Adult Medium Breed Dry Dog Food | D24: 125.39 | E24: AUD | F24: Pet Supplies | G24: PayPal | H24: Confirmed | I24: opalcarabina@gmail.com | J24: Order confirmation email | K24: #82795886 | L24: 198ed58830a90ba3 | M24: Auto Delivery confirmed Aug 27, 2025
B100: TOTAL | D100: =SUMIF(E:E,"AUD",D:D)+SUMIF(E:E,"USD",D:D)*1.5 -> 2642.695

Sheet Jul 2025
A1: Transaction Date | B1: Vendor/Merchant | C1: Description | D1: Amount | E1: Currency | F1: Category | G1: Payment Method | H1: Status | I1: Source Account | J1: Receipt/Invoice | K1: Reference ID | L1: Email ID | M1: Notes
A2: 21/07/2025 | B2: Celonis Inc. (Make.com) | C2: Make Core annual subscription | D2: 108 | E2: USD | F2: Software | G2: American Express | H2: Paid | I2: Gmail | J2: Receipt 2221-6572 | K2: TSDA5NLG-0001 | L2: 1982c21e2db6a1ac
A3: 15/07/2025 | B3: Elementor | C3: Invoice for order | D3: 99 | E3: AUD | F3: Software | G3: Credit Card | H3: Paid | I3: Gmail | J3: Invoice ZINV00850048 | K3: INVIL2500181467 | L3: 1980c16cd05c7ea7 | M3: ESTIMATED - Verify from source
A4: 13/07/2025 | B4: Youly | C4: hubPass subscription | D4: 40 | E4: AUD | F4: Office | G4: Mastercard | H4: Paid | I4: Gmail | J4: Receipt 2410-2361 | K4: 7E1FCEC1-0011 | L4: 1980105aabbd24ea
A5: 12/07/2025 | B5: X | C5: Premium subscription | D5: 120 | E5: AUD | F5: Software | G5: Mastercard | H5: Paid | I5: Gmail | J5: Receipt 2183-5187-0099 | K5: WIMTFPTL-0001 | L5: 197fc3a22f0c6ef2
A6: 11/07/2025 | B6: Glide | C6: Explorer plan (1 year) | D6: 228 | E6: USD | F6: Software | G6: Mastercard | H6: Paid | I6: Gmail | J6: Receipt 2365-9965 | K6: SCMLOVDK-0001 | L6: 197fc6dac6f1599f
A7: 08/07/2025 | B7: MainFunc PTE. LTD. | C7: Genspark Plus Subscription | D7: 263.99 | E7: USD | F7: Software | G7: Link | H7: Paid | I7: Gmail | J7: Receipt 2299-8099 | K7: 5KYQPPPJ-0001 | L7: 197ea4ea3095ec76
A8: 01/07/2025 | B8: Speechify Inc. | C8: Speechify AI Studio Pro | D8: 595 | E8: AUD | F8: Software | G8: American Express | H8: Paid | I8: Gmail | J8: Receipt 2821-2852 | K8: XGLWR541-0000 | L8: 1.978e+15
A9: 2025-07-10 | B9: Letterly | C9: Letterly Pro Code purchase | D9: 79 | E9: USD | F9: Software | G9: Link | H9: Paid | I9: carla@carlorbiz.com.au | J9: Receipt 1977-6194 | K9: 197f4caca9c3de5a | L9: 197f4caca9c3de5a | M9: Letterly Pro Code (charged A$125.52 with conversion)
A10: 2025-07-24 | B10: AppSumo | C10: Formly, personeo.ai, Academy LMS software purchase | D10: 249.7 | E10: USD | F10: Software | G10: PayPal | H10: Paid | I10: opalcarabina@gmail.com | J10: PayPal Receipt | K10: 2S028835SR146920R | L10: 19837de71e501fd3 | M10: Products: Formly (213391), personeo.ai (263110), Academy LMS (272330)
A11: 2025-07-24 | B11: WPManageNinja | C11: WPManageNinja LLC software/plugin | D11: 174 | E11: USD | F11: Software | G11: PayPal | H11: Paid | I11: opalcarabina@gmail.com | J11: PayPal Receipt | L11: 19837e680041c6b6
A12: 2025-07-23 | B12: Google Payment Australia | C12: Google service/subscription payment | D12: 16.99 | E12: AUD | F12: Software | G12: PayPal | H12: Paid | I12: opalcarabina@gmail.com | J12: PayPal Receipt | L12: 198351c6cfe92f5b
A13: 2025-07-22 | B13: Dongguan Lingjian Te | C13: Lifetime plan software/service | D13: 299.99 | E13: USD | F13: Software | G13: PayPal | H13: Paid | I13: opalcarabina@gmail.com | J13: PayPal Receipt | K13: 67N585410P028031F | L13: 1982d71f66d54b8a | M13: innovationm889@gmail.com, +86 132 4983 2591
A14: 2025-07-17 | B14: Pet Circle | C14: Pet supplies order | D14: 264.07 | E14: AUD | F14: Shopping | G14: PayPal | H14: Paid | I14: opalcarabina@gmail.com | J14: PayPal Receipt | K14: 7H577476WM494314X | L14: 198139592d9d28ab | M14: Auto Delivery order a34280eb
A15: 2025-07-17 | B15: Wolf Reborn Limited | C15: Olux Bracelet 1st Gen | D15: 105.78 | E15: AUD | F15: Shopping | G15: PayPal | H15: Paid | I15: opalcarabina@gmail.com | J15: PayPal Receipt, Order #1296371 | K15: 60W678343D501062R | L15: 19813aee39f5f5bc | M15: Olux wearable bracelet, Order ID: rTurkmvuARxttUrwjS0d8HJwp
A16: 2025-07-13 | B16: AppSumo | C16: Qolaba and ClickRank software purchase | D16: 272.8 | E16: USD | F16: Software | G16: PayPal | H16: Paid | I16: opalcarabina@gmail.com | J16: PayPal Receipt | K16: 3AH6328187052772A | L16: 197ff6f51b4e1077 | M16: Qolaba (270613) $169, ClickRank (275276) $79
A17: 2025-07-13 | B17: Envato | C17: Envato Elements subscription | D17: 36.3 | E17: USD | F17: Software | G17: PayPal | H17: Paid | I17: opalcarabina@gmail.com | J17: PayPal Receipt, Order 18371394 | L17: 19801a69fa975daa | M17: Elements $33 subscription
A18: 2025-07-12 | B18: GoDaddy | C18: Websites + Marketing service | D18: 108.49 | E18: AUD | F18: Software | G18: PayPal | H18: Paid | I18: opalcarabina@gmail.com | J18: PayPal Receipt | K18: 5HT580549G7748827 | L18: 197fe647f603b4c0 | M18: GoDaddy Online Services
A19: 2025-07-12 | B19: PayPal Pay in 4 | C19: PayPal Pay in 4 installment payment | D19: 108.39 | E19: AUD | F19: Utilities | G19: Credit Card | H19: Paid | I19: opalcarabina@gmail.com | J19: PayPal Payment Confirmation | L19: 197ff72c0b205b0f | M19: Pay in 4 plan payment, Card ending x-1005
A20: 2025-07-11 | B20: Adobe Systems | C20: Adobe subscription (Creative Cloud or Acrobat) | D20: 31.99 | E20: AUD | F20: Software | G20: PayPal | H20: Paid | I20: opalcarabina@gmail.com | J20: PayPal Authorization, Order AB05404900290EAU | K20: 9WM52274P37690452 | L20: 197f9a2f875d31af | M20: Subtotal $29.08 + Tax $2.91, Card ending 1005
A21: 2025-07-11 | B21: LinkedIn Singapore | C21: LinkedIn subscription or service | D21: 37.49 | E21: AUD | F21: Software | G21: PayPal | H21: Paid | I21: opalcarabina@gmail.com | J21: PayPal Receipt | K21: 40Y39252EE391401E | L21: 197f83e73e64f682 | M21: LinkedIn Singapore Pte Ltd, Card ending 1005
A22: 2025-07-10 | B22: GoDaddy | C22: Websites + Marketing service | D22: 174 | E22: AUD | F22: Software | G22: PayPal | H22: Paid | I22: opalcarabina@gmail.com | J22: PayPal Receipt, Order 3812628367_AUD_17400 | K22: 80K04674A7822950S | L22: 197f472425829708 | M22: GoDaddy Online Services
A23: 2025-07-08 | B23: Dyson | C23: Dyson V11 Advanced ANZ vacuum cleaner | D23: 795 | E23: AUD | F23: Shopping | G23: Credit Card | H23: Paid | I23: opalcarabina@gmail.com | J23: Dyson Order Invoice 6327260521 | K23: 6327260521 | L23: 197e864ee4b8652e | M23: Subtotal $722.73, GST $72.27, Total $795.00
B86: TOTAL | D86: =SUMIF(E:E,"AUD",D:D)+SUMIF(E:E,"USD",D:D)*1.5 -> 5063.87

Sheet Jun 2025
A1: Transaction Date | B1: Vendor/Merchant | C1: Description | D1: Amount | E1: Currency | F1: Category | G1: Payment Method | H1: Status | I1: Source Account | J1: Receipt/Invoice | K1: Reference ID | L1: Email ID | M1: Notes
A2: 13/06/2025 | B2: Youly | C2: hubPass | D2: 40 | E2: AUD | F2: Office | G2: Mastercard | H2: Paid | I2: Gmail | J2: Receipt 2818-1013 | K2: 7E1FCEC1-0010 | L2: 1976688b17f7836e
A3: 11/06/2025 | B3: Amazon.com.au | C3: Order delivered | D3: 89 | E3: AUD | F3: Shopping | G3: Credit Card | H3: Delivered | I3: Gmail | J3: Order 250-0127847-3509467 | K3: 250-0127847-3509467 | L3: 1975c69f37aa449f | M3: ESTIMATED - Verify from source
A4: 2025-06-13 | B4: Youly | C4: hubPass monthly subscription | D4: 59.95 | E4: AUD | F4: Office | G4: Mastercard | H4: Paid | I4: carla@carcouraconsulting.com.au | J4: Receipt 2818-1013, Invoice 7E1FCEC1-0010 | K4: 1976688b17f7836e | L4: 1976688b17f7836e | M4: ESTIMATED - Verify from source
A5: 2025-06-18 | B5: Youly | C5: Mounjaro Kwikpen 2.5 mg/0.6 mL injection | D5: 22.5 | E5: AUD | F5: Health & Wellness | G5: Link | H5: Paid | I5: carla@carcouraconsulting.com.au | J5: Receipt 1783-3202 | K5: 19780a07c8586611 | L5: 19780a07c8586611 | M5: ESTIMATED - Verify from source
A6: 2025-06-14 | B6: TCN Group Pty Ltd | C6: Card.Gift purchase | E6: AUD | F6: Shopping | G6: Credit Card | H6: Paid | I6: carla@carcouraconsulting.com.au | J6: Invoice CG685710 | K6: 1976bfb8113c7154 | L6: 1976bfb8113c7154 | M6: Amount in attachment invoice-CG685710.pdf
A7: 2025-06-01 | B7: Google Workspace | C7: Google Workspace monthly invoice carlorbiz.com.au | E7: AUD | F7: Software | G7: Credit Card | H7: Paid | I7: carla@carcouraconsulting.com.au | J7: Invoice | K7: 1972bffe4950d399 | L7: 1972bffe4950d399 | M7: Amount in attachment PDF
A8: 2025-06-26 | B8: Pet Circle | C8: Pet supplies order via PayPal | D8: 256.5 | E8: AUD | F8: Pet Supplies | G8: PayPal | H8: Paid | I8: opalcarabina@gmail.com | J8: PayPal receipt | K8: 2XR964081J501104R | L8: 197a79680f7f104d | M8: Payment to Pet Circle, delivered to Gisborne VIC
A9: 2025-06-23 | B9: Google Payment Australia | C9: YouTube Premium Subscription | D9: 16.99 | E9: AUD | F9: Entertainment | G9: PayPal | H9: Paid | I9: opalcarabina@gmail.com | J9: PayPal receipt | K9: YouTube Premium | L9: 1979a9dcce6e2694 | M9: Monthly subscription via PayPal
A10: 2025-06-21 | B10: AppSumo | C10: Open eLMS - Product ID: 229171 | D10: 64.9 | E10: USD | F10: Software | G10: PayPal | H10: Paid | I10: opalcarabina@gmail.com | J10: PayPal receipt | K10: 98S97985RP378422M | L10: 1978fc6e124a1e0f | M10: eLearning software purchase
A11: 2025-06-17 | B11: Fantastic Holdings Limited | C11: Adapt Desk | D11: 159 | E11: AUD | F11: Office | G11: PayPal | H11: Paid | I11: opalcarabina@gmail.com | J11: PayPal receipt | K11: 7DS713563S321445M | L11: 1977db379720a199 | M11: Order ID: 8880019151031, delivered to Gisborne VIC
B104: TOTAL | D104: =SUMIF(E:E,"AUD",D:D)+SUMIF(E:E,"USD",D:D)*1.5 -> 741.29

Sheet May 2025
A1: Transaction Date | B1: Vendor/Merchant | C1: Description | D1: Amount | E1: Currency | F1: Category | G1: Payment Method | H1: Status | I1: Source Account | J1: Receipt/Invoice | K1: Reference ID | L1: Email ID | M1: Notes
A2: 15/05/2025 | B2: Squibler | C2: Squibler pro plan | D2: 189.99 | E2: USD | F2: Software | G2: American Express | H2: Paid | I2: Gmail | J2: Receipt 2288-8883 | K2: ECPMYAO8-0002 | L2: 196d395b2b48e251
A3: 2025-05-15 | B3: Youly | C3: hubPass annual subscription renewal | D3: 390.7 | E3: AUD | F3: Office | G3: Link | H3: Paid | I3: carla@carcouraconsulting.com.au | J3: Receipt 1060-3982 | K3: 196d37a0c7ce30f1 | L3: 196d37a0c7ce30f1 | M3: Youly hubPass May 15 payment
A4: 2025-05-11 | B4: Designrr.io - PageOneTraffic Inc | C4: Software subscription invoice | D4: 64 | E4: USD | F4: Software | G4: Credit Card | H4: Paid | I4: carla@carlorbiz.com.au | J4: Invoice 000441163 | K4: 196be7b4dc3597ae | L4: 196be7b4dc3597ae | M4: Amount in email; DUPLICATE - USER REVIEW REQUIRED
A5: 2025-05-11 | B5: Fiction Profits Academy | C5: Course purchase - Payment receipt | D5: 1995 | E5: USD | F5: Education | G5: Credit Card | H5: Paid | I5: carla@carlorbiz.com.au | J5: Receipt 681fede847199433853818b7 | K5: 196bcbc42f7e0e94 | L5: 196bcbc42f7e0e94 | M5: Fiction Profits Academy 30 Day Book Writing Challenge
A6: 2025-05-11 | B6: Fiction Profits Academy | C6: Sales receipt for course purchase | D6: 0 | E6: USD | F6: Education | G6: Credit Card | H6: Paid | I6: carla@carlorbiz.com.au | J6: Sales Receipt | K6: 196bcba6ef5064b3 | L6: 196bcba6ef5064b3 | M6: Duplicate of row 5 - same $1995 purchase
A7: 2025-05-10 | B7: Top Speed Golf | C7: Subscription charge | D7: 149 | E7: USD | F7: Recreation | G7: Credit Card | H7: Paid | I7: Carla@carcouraconsulting.com.au | J7: Subscription #3420896 | K7: 196ba6a3ff3f6399 | L7: 196ba6a3ff3f6399 | M7: All Access Membership (refunded same day)
A8: 2025-05-10 | B8: Messenger Marketing & Consulting, Inc. | C8: The 30 Day Book Writing Challenge + Book Marketing Masterclass | D8: 99 | E8: USD | F8: Education | G8: Credit Card | H8: Paid | I8: carla@carlorbiz.com.au | J8: Order #21121871 | K8: 196b99a3bc909c55 | L8: 196b99a3bc909c55 | M8: Course order; DUPLICATE - USER REVIEW REQUIRED
A9: 2025-05-26 | B9: Chemist Warehouse | C9: PayPal payment for health/pharmacy products | D9: 132.97 | E9: AUD | F9: Health | G9: PayPal | H9: Paid | I9: opalcarabina@gmail.com
A10: 2025-05-26 | B10: Design Bundles Ltd | C10: PayPal payment for digital design resources | D10: 18.99 | E10: USD | F10: Software | G10: PayPal | H10: Paid | I10: opalcarabina@gmail.com
A11: 2025-05-22 | B11: Google Payment Australia | C11: PayPal payment for YouTube Premium subscription | D11: 16.99 | E11: AUD | F11: Entertainment | G11: PayPal | H11: Paid | I11: opalcarabina@gmail.com
A12: 2025-05-20 | B12: GoDaddy.com, LLC | C12: PayPal payment for domain/hosting services | D12: 134.78 | E12: AUD | F12: Software | G12: PayPal | H12: Paid | I12: opalcarabina@gmail.com
A13: 2025-05-18 | B13: PageOneTraffic Inc | C13: PayPal automatic payment for Designrr PRO | D13: 97 | E13: USD | F13: Software | G13: PayPal | H13: Paid | I13: opalcarabina@gmail.com | M13: ""; DUPLICATE - USER REVIEW REQUIRED
A14: 2025-05-15 | B14: Pet Circle | C14: PayPal payment for pet supplies | D14: 159.6 | E14: AUD | F14: Pet Supplies | G14: PayPal | H14: Paid | I14: opalcarabina@gmail.com
A15: 2025-05-14 | B15: THELIVEN | C15: PayPal payment for software/service | D15: 79.99 | E15: USD | F15: Software | G15: PayPal | H15: Paid | I15: opalcarabina@gmail.com
A16: 2025-05-10 | B16: Google Payment Austr... | C16: PayPal payment for Google service | D16: 89.99 | E16: AUD | F16: Software | G16: PayPal | H16: Paid | I16: opalcarabina@gmail.com
A17: 2025-05-10 | B17: Messenger Marketing... | C17: PayPal payment for marketing software/course | D17: 199 | E17: USD | F17: Education | G17: PayPal | H17: Paid | I17: opalcarabina@gmail.com | M17: ""; DUPLICATE - USER REVIEW REQUIRED
A18: 2025-05-09 | B18: AgeMate | C18: PayPal payment for health/longevity supplement | D18: 110.2 | E18: AUD | F18: Health | G18: PayPal | H18: Paid | I18: opalcarabina@gmail.com
A19: 2025-05-09 | B19: ADOBE SYSTEMS PTY LT... | C19: PayPal payment for Adobe subscription | D19: 50.99 | E19: AUD | F19: Software | G19: PayPal | H19: Paid | I19: opalcarabina@gmail.com
A20: 2025-05-01 | B20: Microsoft Pty. Limit... | C20: PayPal payment for Microsoft services | D20: 33 | E20: AUD | F20: Software | G20: PayPal | H20: Paid | I20: opalcarabina@gmail.com
B106: TOTAL | D106: =SUMIF(E:E,"AUD",D:D)+SUMIF(E:E,"USD",D:D)*1.5 -> 5457.175

Sheet Apr 2025
A1: Transaction Date | B1: Vendor/Merchant | C1: Description | D1: Amount | E1: Currency | F1: Category | G1: Payment Method | H1: Status | I1: Source Account | J1: Receipt/Invoice | K1: Reference ID | L1: Email ID | M1: Notes
A2: 01/04/2025 | B2: ALDImobile | C2: Service activation | D2: 30 | E2: AUD | F2: Utilities | G2: Credit Card | H2: Paid | I2: Gmail | J2: Order 214980729 | K2: 8485815 | L2: 195ef5995559abef | M2: ESTIMATED - Verify from source
A3: 2025-04-16 | B3: Booking.com | C3: Duporth - Luxury Riverfront Apartment accommodation (Check-in: Jun 24 2026, Check-out: Jun 30 2026) | D3: 1599.28 | E3: AUD | F3: Travel | G3: Credit Card | H3: Paid | I3: carla@carcouraconsulting.com.au | J3: Booking number 4676746078 | K3: 1963d86529af8575 | L3: 1963d86529af8575 | M3: Maroochydore Australia 6-night stay paid in advance; DUPLICATE - USER REVIEW REQUIRED
A4: 2025-04-27 | B4: H&M Hennes & Mauritz | C4: PayPal payment | D4: 149.74 | E4: AUD | F4: Apparel | G4: PayPal | H4: Paid | I4: opalcarabina@gmail.com
A5: 2025-04-27 | B5: Temu.com | C5: PayPal payment | D5: 114.98 | E5: AUD | F5: Shopping | G5: PayPal | H5: Paid | I5: opalcarabina@gmail.com
A6: 2025-04-27 | B6: Temu.com | C6: PayPal payment | D6: 44.96 | E6: AUD | F6: Shopping | G6: PayPal | H6: Paid | I6: opalcarabina@gmail.com
A7: 2025-04-26 | B7: Design Bundles Ltd | C7: PayPal payment | D7: 18.99 | E7: USD | F7: Software | G7: PayPal | H7: Paid | I7: opalcarabina@gmail.com
A8: 2025-04-25 | B8: GoDaddy.com LLC | C8: PayPal payment | D8: 163.09 | E8: AUD | F8: Software | G8: PayPal | H8: Paid | I8: opalcarabina@gmail.com
A9: 2025-04-25 | B9: GoDaddy.com LLC | C9: PayPal payment | D9: 132.34 | E9: AUD | F9: Software | G9: PayPal | H9: Paid | I9: opalcarabina@gmail.com
A10: 2025-04-25 | B10: PIXLR Pte Ltd | C10: PayPal payment | D10: 16.09 | E10: USD | F10: Software | G10: PayPal | H10: Paid | I10: opalcarabina@gmail.com
A11: 2025-04-24 | B11: Pet Circle | C11: PayPal payment | D11: 158.65 | E11: AUD | F11: Pet Supplies | G11: PayPal | H11: Paid | I11: opalcarabina@gmail.com
A12: 2025-04-23 | B12: Google Payment Australia | C12: PayPal payment | D12: 16.99 | E12: AUD | F12: Entertainment | G12: PayPal | H12: Paid | I12: opalcarabina@gmail.com
